Workbook

Sheet NPC Dialogue
A1: KEY | B1: town_type | C1: town_name | D1: _npc_name | E1: keyword | F1: reply | G1: TriggersQuestion | H1: question | I1: qn_yes | J1: qn_no | K1: humility_related_flag
A2: =C2&"|"&D2&"|"&E2 -> Britain|Bartender|Black stone (20 gold) | B2: Towns | C2: Britain | D2: Bartender | E2: Black stone (20 gold) | F2: Ah, the Black Stone. Yes I’ve heard of it. But, the only one who knows where it lies is the wizard Merlin. | G2: =IF(ISNA(VLOOKUP(B2&"|"&C2&"|"&D2&"|"&E2,QuestionTriggers!A:F,6,FALSE)),"","--->")
A3: =C3&"|"&D3&"|"&E3 -> Britain|Bridge Guard|BRID | B3: Towns | C3: Britain | D3: Bridge Guard | E3: BRID | F3: Across the bridge our people dance and sing! | G3: =IF(ISNA(VLOOKUP(B3&"|"&C3&"|"&D3&"|"&E3,QuestionTriggers!A:F,6,FALSE)),"","--->") | H3: Would thou like to join them? | I3: Remember, an open heart is the first step on the path to wisdom! | J3: Then you have no business across the bridge.
A4: =C4&"|"&D4&"|"&E4 -> Britain|Bridge Guard|GUAR | B4: Towns | C4: Britain | D4: Bridge Guard | E4: GUAR | F4: Yep. | G4: =IF(ISNA(VLOOKUP(B4&"|"&C4&"|"&D4&"|"&E4,QuestionTriggers!A:F,6,FALSE)),"","--->") -> ---> | H4: Would thou like to join them? | I4: Remember, an open heart is the first step on the path to wisdom! | J4: Then you have no business across the bridge.
A5: =C5&"|"&D5&"|"&E5 -> Britain|Bridge Guard|HEALTH | B5: Towns | C5: Britain | D5: Bridge Guard | E5: HEALTH | F5: Good. | G5: =IF(ISNA(VLOOKUP(B5&"|"&C5&"|"&D5&"|"&E5,QuestionTriggers!A:F,6,FALSE)),"","--->") | H5: Would thou like to join them? | I5: Remember, an open heart is the first step on the path to wisdom! | J5: Then you have no business across the bridge.
A6: =C6&"|"&D6&"|"&E6 -> Britain|Bridge Guard|JOB | B6: Towns | C6: Britain | D6: Bridge Guard | E6: JOB | F6: I guard the bridge. | G6: =IF(ISNA(VLOOKUP(B6&"|"&C6&"|"&D6&"|"&E6,QuestionTriggers!A:F,6,FALSE)),"","--->") | H6: Would thou like to join them? | I6: Remember, an open heart is the first step on the path to wisdom! | J6: Then you have no business across the bridge.
A7: =C7&"|"&D7&"|"&E7 -> Britain|Bridge Guard|LOOK | B7: Towns | C7: Britain | D7: Bridge Guard | E7: LOOK | F7: A guard | G7: =IF(ISNA(VLOOKUP(B7&"|"&C7&"|"&D7&"|"&E7,QuestionTriggers!A:F,6,FALSE)),"","--->") | H7: Would thou like to join them? | I7: Remember, an open heart is the first step on the path to wisdom! | J7: Then you have no business across the bridge.
A8: =C8&"|"&D8&"|"&E8 -> Britain|Bridge Guard|NAME | B8: Towns | C8: Britain | D8: Bridge Guard | E8: NAME | F8: a guard | G8: =IF(ISNA(VLOOKUP(B8&"|"&C8&"|"&D8&"|"&E8,QuestionTriggers!A:F,6,FALSE)),"","--->") | H8: Would thou like to join them? | I8: Remember, an open heart is the first step on the path to wisdom! | J8: Then you have no business across the bridge.
A9: =C9&"|"&D9&"|"&E9 -> Britain|Child|COMP | B9: Towns | C9: Britain | D9: Child | E9: COMP | F9: Never care so much for thyself that thou cannot care for others! | G9: =IF(ISNA(VLOOKUP(B9&"|"&C9&"|"&D9&"|"&E9,QuestionTriggers!A:F,6,FALSE)),"","--->") -> ---> | H9: Know ye the mantra of compassion? | I9: Good. | J9: Ask Cricket!
A10: =C10&"|"&D10&"|"&E10 -> Britain|Child|HEALTH | B10: Towns | C10: Britain | D10: Child | E10: HEALTH | F10: O.K. | G10: =IF(ISNA(VLOOKUP(B10&"|"&C10&"|"&D10&"|"&E10,QuestionTriggers!A:F,6,FALSE)),"","--->") | H10: Know ye the mantra of compassion? | I10: Good. | J10: Ask Cricket!
A11: =C11&"|"&D11&"|"&E11 -> Britain|Child|JOB | B11: Towns | C11: Britain | D11: Child | E11: JOB | F11: I am learning compassion. | G11: =IF(ISNA(VLOOKUP(B11&"|"&C11&"|"&D11&"|"&E11,QuestionTriggers!A:F,6,FALSE)),"","--->") | H11: Know ye the mantra of compassion? | I11: Good. | J11: Ask Cricket!
A12: =C12&"|"&D12&"|"&E12 -> Britain|Child|LEAR | B12: Towns | C12: Britain | D12: Child | E12: LEAR | F12: The solution to ones problems often lies in solving others! | G12: =IF(ISNA(VLOOKUP(B12&"|"&C12&"|"&D12&"|"&E12,QuestionTriggers!A:F,6,FALSE)),"","--->") | H12: Know ye the mantra of compassion? | I12: Good. | J12: Ask Cricket!
A13: =C13&"|"&D13&"|"&E13 -> Britain|Child|LOOK | B13: Towns | C13: Britain | D13: Child | E13: LOOK | F13: A small child | G13: =IF(ISNA(VLOOKUP(B13&"|"&C13&"|"&D13&"|"&E13,QuestionTriggers!A:F,6,FALSE)),"","--->") | H13: Know ye the mantra of compassion? | I13: Good. | J13: Ask Cricket!
A14: =C14&"|"&D14&"|"&E14 -> Britain|Child|NAME | B14: Towns | C14: Britain | D14: Child | E14: NAME | F14: a child | G14: =IF(ISNA(VLOOKUP(B14&"|"&C14&"|"&D14&"|"&E14,QuestionTriggers!A:F,6,FALSE)),"","--->") | H14: Know ye the mantra of compassion? | I14: Good. | J14: Ask Cricket!
... A44: =C44&"|"&D44&"|"&E44 -> Britain|Joe|STON | B44: Towns | C44: Britain | D44: Joe | E44: STON | F44: The yellow stone is in the dungeon Despise... | G44: =IF(ISNA(VLOOKUP(B44&"|"&C44&"|"&D44&"|"&E44,QuestionTriggers!A:F,6,FALSE)),"","--->") | H44: Give me rum?... | I44: Thanxth... my friend Joe can help with the stones... hic... | J44: Ah, be a joe!
A45: =C45&"|"&D45&"|"&E45 -> Britain|Julio|COMP | B45: Towns | C45: Britain | D45: Julio | E45: COMP | F45: Compassion derives itself from unending love! | G45: =IF(ISNA(VLOOKUP(B45&"|"&C45&"|"&D45&"|"&E45,QuestionTriggers!A:F,6,FALSE)),"","--->") -> ---> | H45: Dost thou know the true nature of all things? | I45: Thou art a liar and a braggart. | J45: No mortal can. | K45: NO improves Humility
A46: =C46&"|"&D46&"|"&E46 -> Britain|Julio|HEALTH | B46: Towns | C46: Britain | D46: Julio | E46: HEALTH | F46: Solemn. | G46: =IF(ISNA(VLOOKUP(B46&"|"&C46&"|"&D46&"|"&E46,QuestionTriggers!A:F,6,FALSE)),"","--->") | H46: Dost thou know the true nature of all things? | I46: Thou art a liar and a braggart. | J46: No mortal can. | K46: NO improves Humility
A47: =C47&"|"&D47&"|"&E47 -> Britain|Julio|JOB | B47: Towns | C47: Britain | D47: Julio | E47: JOB | F47: I seek the true nature of things! | G47: =IF(ISNA(VLOOKUP(B47&"|"&C47&"|"&D47&"|"&E47,QuestionTriggers!A:F,6,FALSE)),"","--->") | H47: Dost thou know the true nature of all things? | I47: Thou art a liar and a braggart. | J47: No mortal can. | K47: NO improves Humility
A48: =C48&"|"&D48&"|"&E48 -> Britain|Julio|LOOK | B48: Towns | C48: Britain | D48: Julio | E48: LOOK | F48: A solemn bard. | G48: =IF(ISNA(VLOOKUP(B48&"|"&C48&"|"&D48&"|"&E48,QuestionTriggers!A:F,6,FALSE)),"","--->") | H48: Dost thou know the true nature of all things? | I48: Thou art a liar and a braggart. | J48: No mortal can. | K48: NO improves Humility
A49: =C49&"|"&D49&"|"&E49 -> Britain|Julio|NAME | B49: Towns | C49: Britain | D49: Julio | E49: NAME | F49: Julio | G49: =IF(ISNA(VLOOKUP(B49&"|"&C49&"|"&D49&"|"&E49,QuestionTriggers!A:F,6,FALSE)),"","--->") | H49: Dost thou know the true nature of all things? | I49: Thou art a liar and a braggart. | J49: No mortal can. | K49: NO improves Humility
A50: =C50&"|"&D50&"|"&E50 -> Britain|Julio|NATU | B50: Towns | C50: Britain | D50: Julio | E50: NATU | F50: All things have a true nature! | G50: =IF(ISNA(VLOOKUP(B50&"|"&C50&"|"&D50&"|"&E50,QuestionTriggers!A:F,6,FALSE)),"","--->") | H50: Dost thou know the true nature of all things? | I50: Thou art a liar and a braggart. | J50: No mortal can. | K50: NO improves Humility
A51: =C51&"|"&D51&"|"&E51 -> Britain|Mentor|HEALTH | B51: Towns | C51: Britain | D51: Mentor | E51: HEALTH | F51: I am well. | G51: =IF(ISNA(VLOOKUP(B51&"|"&C51&"|"&D51&"|"&E51,QuestionTriggers!A:F,6,FALSE)),"","--->") | H51: Art thou proud? | I51: That is not a virtue! | J51: Pride exists without truth, love, or courage! | K51: NO improves Humility
A52: =C52&"|"&D52&"|"&E52 -> Britain|Mentor|JOB | B52: Towns | C52: Britain | D52: Mentor | E52: JOB | F52: I escaped Magincia! | G52: =IF(ISNA(VLOOKUP(B52&"|"&C52&"|"&D52&"|"&E52,QuestionTriggers!A:F,6,FALSE)),"","--->") | H52: Art thou proud? | I52: That is not a virtue! | J52: Pride exists without truth, love, or courage! | K52: NO improves Humility
A53: =C53&"|"&D53&"|"&E53 -> Britain|Mentor|LOOK | B53: Towns | C53: Britain | D53: Mentor | E53: LOOK | F53: A wise shepherd. | G53: =IF(ISNA(VLOOKUP(B53&"|"&C53&"|"&D53&"|"&E53,QuestionTriggers!A:F,6,FALSE)),"","--->") | H53: Art thou proud? | I53: That is not a virtue! | J53: Pride exists without truth, love, or courage! | K53: NO improves Humility
A54: =C54&"|"&D54&"|"&E54 -> Britain|Mentor|MAGI | B54: Towns | C54: Britain | D54: Mentor | E54: MAGI | F54: Pride was too great in Magincia! | G54: =IF(ISNA(VLOOKUP(B54&"|"&C54&"|"&D54&"|"&E54,QuestionTriggers!A:F,6,FALSE)),"","--->") | H54: Art thou proud? | I54: That is not a virtue! | J54: Pride exists without truth, love, or courage! | K54: NO improves Humility
A55: =C55&"|"&D55&"|"&E55 -> Britain|Mentor|NAME | B55: Towns | C55: Britain | D55: Mentor | E55: NAME | F55: Mentor | G55: =IF(ISNA(VLOOKUP(B55&"|"&C55&"|"&D55&"|"&E55,QuestionTriggers!A:F,6,FALSE)),"","--->") | H55: Art thou proud? | I55: That is not a virtue! | J55: Pride exists without truth, love, or courage! | K55: NO improves Humility
A56: =C56&"|"&D56&"|"&E56 -> Britain|Mentor|PRID | B56: Towns | C56: Britain | D56: Mentor | E56: PRID | F56: The city was destroyed by daemons for its pride! | G56: =IF(ISNA(VLOOKUP(B56&"|"&C56&"|"&D56&"|"&E56,QuestionTriggers!A:F,6,FALSE)),"","--->") -> ---> | H56: Art thou proud? | I56: That is not a virtue! | J56: Pride exists without truth, love, or courage! | K56: NO improves Humility
A57: =C57&"|"&D57&"|"&E57 -> Britain|Pepper|BARD | B57: Towns | C57: Britain | D57: Pepper | E57: BARD | F57: Bards know many things. | G57: =IF(ISNA(VLOOKUP(B57&"|"&C57&"|"&D57&"|"&E57,QuestionTriggers!A:F,6,FALSE)),"","--->") | H57: Dost thou seek something? | I57: What might that be? | J57: Alas, I may have been able to help.
A58: =C58&"|"&D58&"|"&E58 -> Britain|Pepper|HEALTH | B58: Towns | C58: Britain | D58: Pepper | E58: HEALTH | F58: Healthy. | G58: =IF(ISNA(VLOOKUP(B58&"|"&C58&"|"&D58&"|"&E58,QuestionTriggers!A:F,6,FALSE)),"","--->") | H58: Dost thou seek something? | I58: What might that be? | J58: Alas, I may have been able to help.
A59: =C59&"|"&D59&"|"&E59 -> Britain|Pepper|JOB | B59: Towns | C59: Britain | D59: Pepper | E59: JOB | F59: I am a fighting bard. | G59: =IF(ISNA(VLOOKUP(B59&"|"&C59&"|"&D59&"|"&E59,QuestionTriggers!A:F,6,FALSE)),"","--->") | H59: Dost thou seek something? | I59: What might that be? | J59: Alas, I may have been able to help.
A60: =C60&"|"&D60&"|"&E60 -> Britain|Pepper|LOOK | B60: Towns | C60: Britain | D60: Pepper | E60: LOOK | F60: A spicy woman. | G60: =IF(ISNA(VLOOKUP(B60&"|"&C60&"|"&D60&"|"&E60,QuestionTriggers!A:F,6,FALSE)),"","--->") | H60: Dost thou seek something? | I60: What might that be? | J60: Alas, I may have been able to help.
A61: =C61&"|"&D61&"|"&E61 -> Britain|Pepper|NAME | B61: Towns | C61: Britain | D61: Pepper | E61: NAME | F61: Pepper | G61: =IF(ISNA(VLOOKUP(B61&"|"&C61&"|"&D61&"|"&E61,QuestionTriggers!A:F,6,FALSE)),"","--->") | H61: Dost thou seek something? | I61: What might that be? | J61: Alas, I may have been able to help.
A62: =C62&"|"&D62&"|"&E62 -> Britain|Pepper|RUNE | B62: Towns | C62: Britain | D62: Pepper | E62: RUNE | F62: The rune of compassion lies at the end of a hall somewhere in this towne. | G62: =IF(ISNA(VLOOKUP(B62&"|"&C62&"|"&D62&"|"&E62,QuestionTriggers!A:F,6,FALSE)),"","--->") -> ---> | H62: Dost thou seek something? | I62: What might that be? | J62: Alas, I may have been able to help.
A63: =C63&"|"&D63&"|"&E63 -> Britain|Sebastian|HEALTH | B63: Towns | C63: Britain | D63: Sebastian | E63: HEALTH | F63: Not so well. | G63: =IF(ISNA(VLOOKUP(B63&"|"&C63&"|"&D63&"|"&E63,QuestionTriggers!A:F,6,FALSE)),"","--->") | H63: Wilt thou find and destroy it? | I63: Then ask at the pub there of the skull! | J63: Oh.
A64: =C64&"|"&D64&"|"&E64 -> Britain|Sebastian|JOB | B64: Towns | C64: Britain | D64: Sebastian | E64: JOB | F64: I know a terrible secret! | G64: =IF(ISNA(VLOOKUP(B64&"|"&C64&"|"&D64&"|"&E64,QuestionTriggers!A:F,6,FALSE)),"","--->") | H64: Wilt thou find and destroy it? | I64: Then ask at the pub there of the skull! | J64: Oh.
A65: =C65&"|"&D65&"|"&E65 -> Britain|Sebastian|LOOK | B65: Towns | C65: Britain | D65: Sebastian | E65: LOOK | F65: An injured person. | G65: =IF(ISNA(VLOOKUP(B65&"|"&C65&"|"&D65&"|"&E65,QuestionTriggers!A:F,6,FALSE)),"","--->") | H65: Wilt thou find and destroy it? | I65: Then ask at the pub there of the skull! | J65: Oh.
A66: =C66&"|"&D66&"|"&E66 -> Britain|Sebastian|MOND | B66: Towns | C66: Britain | D66: Sebastian | E66: MOND | F66: An artifact remains! I heard at Buccaneer’s Den! | G66: =IF(ISNA(VLOOKUP(B66&"|"&C66&"|"&D66&"|"&E66,QuestionTriggers!A:F,6,FALSE)),"","--->") -> ---> | H66: Wilt thou find and destroy it? | I66: Then ask at the pub there of the skull! | J66: Oh.
A67: =C67&"|"&D67&"|"&E67 -> Britain|Sebastian|NAME | B67: Towns | C67: Britain | D67: Sebastian | E67: NAME | F67: Sebastian | G67: =IF(ISNA(VLOOKUP(B67&"|"&C67&"|"&D67&"|"&E67,QuestionTriggers!A:F,6,FALSE)),"","--->") | H67: Wilt thou find and destroy it? | I67: Then ask at the pub there of the skull! | J67: Oh.
A68: =C68&"|"&D68&"|"&E68 -> Britain|Sebastian|SECR | B68: Towns | C68: Britain | D68: Sebastian | E68: SECR | F68: Mondain’s influence has not left the world! | G68: =IF(ISNA(VLOOKUP(B68&"|"&C68&"|"&D68&"|"&E68,QuestionTriggers!A:F,6,FALSE)),"","--->") | H68: Wilt thou find and destroy it? | I68: Then ask at the pub there of the skull! | J68: Oh.
... A98: =C98&"|"&D98&"|"&E98 -> Britain|Thevel|ORBS | B98: Towns | C98: Britain | D98: Thevel | E98: ORBS | F98: A one-handed beggar knows their secrets! | G98: =IF(ISNA(VLOOKUP(B98&"|"&C98&"|"&D98&"|"&E98,QuestionTriggers!A:F,6,FALSE)),"","--->") | H98: Hast thou seen him? | I98: Only he knows the orb’s gift! | J98: Find him in Serpent castle for he knows of orbs!
...

Sheet MC-NPC_TAGS
A1: _town_name | B1: npc_name | C1: LOOK_value | D1: MC Profession | E1: Name-the-NPC | F1: InvisiTag-the-NPC | H1: NPC TAG
A2: Moonglow | B2: Browning | C2: =VLOOKUP(A2&"|"&B2&"|"&"LOOK",'NPC Dialogue'!$A:$F,6,FALSE) -> A tall mage. | E2: ="/data merge entity @e[type=minecraft:villager,limit=1,sort=nearest] {CustomName:"""&B2&"""}" -> /data merge entity @e[type=minecraft:villager,limit=1,sort=nearest] {CustomName:"Browning"} | F2: ="/tag @e[type=minecraft:villager,name="""&B2&""",limit=1] add npc_"&LOWER(B2) -> /tag @e[type=minecraft:villager,name="Browning",limit=1] add npc_browning
A3: Moonglow | B3: Calabrini | C3: =VLOOKUP(A3&"|"&B3&"|"&"LOOK",'NPC Dialogue'!$A:$F,6,FALSE) -> A tall mage. | E3: ="/data merge entity @e[type=minecraft:villager,limit=1,sort=nearest] {CustomName:"""&B3&"""}" -> /data merge entity @e[type=minecraft:villager,limit=1,sort=nearest] {CustomName:"Calabrini"} | F3: ="/tag @e[type=minecraft:villager,name="""&B3&""",limit=1] add npc_"&LOWER(B3) -> /tag @e[type=minecraft:villager,name="Calabrini",limit=1] add npc_calabrini
A4: Moonglow | B4: Christen | C4: =VLOOKUP(A4&"|"&B4&"|"&"LOOK",'NPC Dialogue'!$A:$F,6,FALSE) -> The housekeeping nitwit. | E4: ="/data merge entity @e[type=minecraft:villager,limit=1,sort=nearest] {CustomName:"""&B4&"""}" -> /data merge entity @e[type=minecraft:villager,limit=1,sort=nearest] {CustomName:"Christen"} | F4: ="/tag @e[type=minecraft:villager,name="""&B4&""",limit=1] add npc_"&LOWER(B4) -> /tag @e[type=minecraft:villager,name="Christen",limit=1] add npc_christen
A5: Moonglow | B5: Cosima | C5: =VLOOKUP(A5&"|"&B5&"|"&"LOOK",'NPC Dialogue'!$A:$F,6,FALSE) -> An elderly woman | E5: ="/data merge entity @e[type=minecraft:villager,limit=1,sort=nearest] {CustomName:"""&B5&"""}" -> /data merge entity @e[type=minecraft:villager,limit=1,sort=nearest] {CustomName:"Cosima"} | F5: ="/tag @e[type=minecraft:villager,name="""&B5&""",limit=1] add npc_"&LOWER(B5) -> /tag @e[type=minecraft:villager,name="Cosima",limit=1] add npc_cosima
A6: Moonglow | B6: Cromwell | C6: =VLOOKUP(A6&"|"&B6&"|"&"LOOK",'NPC Dialogue'!$A:$F,6,FALSE) -> I am a regal palladin. | E6: ="/data merge entity @e[type=minecraft:villager,limit=1,sort=nearest] {CustomName:"""&B6&"""}" -> /data merge entity @e[type=minecraft:villager,limit=1,sort=nearest] {CustomName:"Cromwell"} | F6: ="/tag @e[type=minecraft:villager,name="""&B6&""",limit=1] add npc_"&LOWER(B6) -> /tag @e[type=minecraft:villager,name="Cromwell",limit=1] add npc_cromwell
A7: Moonglow | B7: Daranor | C7: =VLOOKUP(A7&"|"&B7&"|"&"LOOK",'NPC Dialogue'!$A:$F,6,FALSE) -> A hunched, insane looking man! | E7: ="/data merge entity @e[type=minecraft:villager,limit=1,sort=nearest] {CustomName:"""&B7&"""}" -> /data merge entity @e[type=minecraft:villager,limit=1,sort=nearest] {CustomName:"Daranor"} | F7: ="/tag @e[type=minecraft:villager,name="""&B7&""",limit=1] add npc_"&LOWER(B7) -> /tag @e[type=minecraft:villager,name="Daranor",limit=1] add npc_daranor
A8: Moonglow | B8: Dekker | C8: =VLOOKUP(A8&"|"&B8&"|"&"LOOK",'NPC Dialogue'!$A:$F,6,FALSE) -> A bouncy jester | E8: ="/data merge entity @e[type=minecraft:villager,limit=1,sort=nearest] {CustomName:"""&B8&"""}" -> /data merge entity @e[type=minecraft:villager,limit=1,sort=nearest] {CustomName:"Dekker"} | F8: ="/tag @e[type=minecraft:villager,name="""&B8&""",limit=1] add npc_"&LOWER(B8) -> /tag @e[type=minecraft:villager,name="Dekker",limit=1] add npc_dekker
A9: Moonglow | B9: Inoo | C9: =VLOOKUP(A9&"|"&B9&"|"&"LOOK",'NPC Dialogue'!$A:$F,6,FALSE) -> An old gypsy. | E9: ="/data merge entity @e[type=minecraft:villager,limit=1,sort=nearest] {CustomName:"""&B9&"""}" -> /data merge entity @e[type=minecraft:villager,limit=1,sort=nearest] {CustomName:"Inoo"} | F9: ="/tag @e[type=minecraft:villager,name="""&B9&""",limit=1] add npc_"&LOWER(B9) -> /tag @e[type=minecraft:villager,name="Inoo",limit=1] add npc_inoo
A10: Moonglow | B10: Mariah | C10: =VLOOKUP(A10&"|"&B10&"|"&"LOOK",'NPC Dialogue'!$A:$F,6,FALSE) -> A young mage | E10: ="/data merge entity @e[type=minecraft:villager,limit=1,sort=nearest] {CustomName:"""&B10&"""}" -> /data merge entity @e[type=minecraft:villager,limit=1,sort=nearest] {CustomName:"Mariah"} | F10: ="/tag @e[type=minecraft:villager,name="""&B10&""",limit=1] add npc_"&LOWER(B10) -> /tag @e[type=minecraft:villager,name="Mariah",limit=1] add npc_mariah
A11: Moonglow | B11: Patric the Humble Shepherd | C11: =VLOOKUP(A11&"|"&B11&"|"&"LOOK",'NPC Dialogue'!$A:$F,6,FALSE) -> A meek shepherd. | E11: ="/data merge entity @e[type=minecraft:villager,limit=1,sort=nearest] {CustomName:"""&B11&"""}" -> /data merge entity @e[type=minecraft:villager,limit=1,sort=nearest] {CustomName:"Patric the Humble Shepherd"} | F11: /tag @e[type=minecraft:villager,name="Patric the Humble Shepherd",limit=1] add npc_patric_the_humble_shepherd
A12: Moonglow | B12: Rebelias | C12: =VLOOKUP(A12&"|"&B12&"|"&"LOOK",'NPC Dialogue'!$A:$F,6,FALSE) -> A mystic wizard. | E12: ="/data merge entity @e[type=minecraft:villager,limit=1,sort=nearest] {CustomName:"""&B12&"""}" -> /data merge entity @e[type=minecraft:villager,limit=1,sort=nearest] {CustomName:"Rebelias"} | F12: ="/tag @e[type=minecraft:villager,name="""&B12&""",limit=1] add npc_"&LOWER(B12) -> /tag @e[type=minecraft:villager,name="Rebelias",limit=1] add npc_rebelias
A13: Moonglow | B13: Scatu | C13: =VLOOKUP(A13&"|"&B13&"|"&"LOOK",'NPC Dialogue'!$A:$F,6,FALSE) -> I am the Proprietor of Inn | E13: ="/data merge entity @e[type=minecraft:villager,limit=1,sort=nearest] {CustomName:"""&B13&"""}" -> /data merge entity @e[type=minecraft:villager,limit=1,sort=nearest] {CustomName:"Scatu"} | F13: ="/tag @e[type=minecraft:villager,name="""&B13&""",limit=1] add npc_"&LOWER(B13) -> /tag @e[type=minecraft:villager,name="Scatu",limit=1] add npc_scatu
A14: Moonglow | B14: Shakespeare | C14: =VLOOKUP(A14&"|"&B14&"|"&"LOOK",'NPC Dialogue'!$A:$F,6,FALSE) -> A wise wizard. | E14: ="/data merge entity @e[type=minecraft:villager,limit=1,sort=nearest] {CustomName:"""&B14&"""}" -> /data merge entity @e[type=minecraft:villager,limit=1,sort=nearest] {CustomName:"Shakespeare"} | F14: ="/tag @e[type=minecraft:villager,name="""&B14&""",limit=1] add npc_"&LOWER(B14) -> /tag @e[type=minecraft:villager,name="Shakespeare",limit=1] add npc_shakespeare
A15: Moonglow | B15: Shazom | C15: =VLOOKUP(A15&"|"&B15&"|"&"LOOK",'NPC Dialogue'!$A:$F,6,FALSE) -> A dying young wizard. | E15: ="/data merge entity @e[type=minecraft:villager,limit=1,sort=nearest] {CustomName:"""&B15&"""}" -> /data merge entity @e[type=minecraft:villager,limit=1,sort=nearest] {CustomName:"Shazom"} | F15: ="/tag @e[type=minecraft:villager,name="""&B15&""",limit=1] add npc_"&LOWER(B15) -> /tag @e[type=minecraft:villager,name="Shazom",limit=1] add npc_shazom
A16: Moonglow | B16: Tracie | C16: =VLOOKUP(A16&"|"&B16&"|"&"LOOK",'NPC Dialogue'!$A:$F,6,FALSE) -> Starving journalist | E16: ="/data merge entity @e[type=minecraft:villager,limit=1,sort=nearest] {CustomName:"""&B16&"""}" -> /data merge entity @e[type=minecraft:villager,limit=1,sort=nearest] {CustomName:"Tracie"} | F16: ="/tag @e[type=minecraft:villager,name="""&B16&""",limit=1] add npc_"&LOWER(B16) -> /tag @e[type=minecraft:villager,name="Tracie",limit=1] add npc_tracie
A17: Moonglow | B17: Tyrone | C17: =VLOOKUP(A17&"|"&B17&"|"&"LOOK",'NPC Dialogue'!$A:$F,6,FALSE) -> A battered mage. | E17: ="/data merge entity @e[type=minecraft:villager,limit=1,sort=nearest] {CustomName:"""&B17&"""}" -> /data merge entity @e[type=minecraft:villager,limit=1,sort=nearest] {CustomName:"Tyrone"} | F17: ="/tag @e[type=minecraft:villager,name="""&B17&""",limit=1] add npc_"&LOWER(B17) -> /tag @e[type=minecraft:villager,name="Tyrone",limit=1] add npc_tyrone
A18: Moonglow | B18: William | C18: =VLOOKUP(A18&"|"&B18&"|"&"LOOK",'NPC Dialogue'!$A:$F,6,FALSE) -> A Nitwit eating a sandwich. | E18: ="/data merge entity @e[type=minecraft:villager,limit=1,sort=nearest] {CustomName:"""&B18&"""}" -> /data merge entity @e[type=minecraft:villager,limit=1,sort=nearest] {CustomName:"William"} | F18: ="/tag @e[type=minecraft:villager,name="""&B18&""",limit=1] add npc_"&LOWER(B18) -> /tag @e[type=minecraft:villager,name="William",limit=1] add npc_william
A19: Moonglow | B19: Shaman | C19: =VLOOKUP(A19&"|"&B19&"|"&"LOOK",'NPC Dialogue'!$A:$F,6,FALSE) -> I am the Proprietor of Sage Deli, here. | E19: ="/data merge entity @e[type=minecraft:villager,limit=1,sort=nearest] {CustomName:"""&B19&"""}" -> /data merge entity @e[type=minecraft:villager,limit=1,sort=nearest] {CustomName:"Shaman"} | F19: ="/tag @e[type=minecraft:villager,name="""&B19&""",limit=1] add npc_"&LOWER(B19) -> /tag @e[type=minecraft:villager,name="Shaman",limit=1] add npc_shaman
A20: Moonglow | B20: Harmony | C20: =VLOOKUP(A20&"|"&B20&"|"&"LOOK",'NPC Dialogue'!$A:$F,6,FALSE) -> I am the Proprietor of The Healer shoppe. | E20: ="/data merge entity @e[type=minecraft:villager,limit=1,sort=nearest] {CustomName:"""&B20&"""}" -> /data merge entity @e[type=minecraft:villager,limit=1,sort=nearest] {CustomName:"Harmony"} | F20: ="/tag @e[type=minecraft:villager,name="""&B20&""",limit=1] add npc_"&LOWER(B20) -> /tag @e[type=minecraft:villager,name="Harmony",limit=1] add npc_harmony
A21: Moonglow | B21: Margot | C21: =IF(ISNA(VLOOKUP(A21&"|"&B21&"|"&"LOOK",'NPC Dialogue'!$A:$F,6,FALSE)),VLOOKUP(A21&"|"&B21&"|"&"You see...",'NPC Dialogue'!$A:$F,6,FALSE),VLOOKUP(A21&"|"&B21&"|"&"LOOK",'NPC Dialogue'!$A:$F,6,FALSE)) -> I am the Propriety of Magical Herbs | E21: ="/data merge entity @e[type=minecraft:villager,limit=1,sort=nearest] {CustomName:"""&B21&"""}" -> /data merge entity @e[type=minecraft:villager,limit=1,sort=nearest] {CustomName:"Margot"} | F21: ="/tag @e[type=minecraft:villager,name="""&B21&""",limit=1] add npc_"&LOWER(B21) -> /tag @e[type=minecraft:villager,name="Margot",limit=1] add npc_margot
A22: Trinsic | B22: Aristotle | C22: =IF(ISNA(VLOOKUP(A22&"|"&B22&"|"&"LOOK",'NPC Dialogue'!$A:$F,6,FALSE)),VLOOKUP(A22&"|"&B22&"|"&"You see..",'NPC Dialogue'!$A:$F,6,FALSE),VLOOKUP(A22&"|"&B22&"|"&"LOOK",'NPC Dialogue'!$A:$F,6,FALSE)) -> A dignified paladin. | D22: Cartographer | E22: ="/data merge entity @e[type=minecraft:villager,limit=1,sort=nearest] {CustomName:"""&B22&"""}" -> /data merge entity @e[type=minecraft:villager,limit=1,sort=nearest] {CustomName:"Aristotle"} | F22: ="/tag @e[type=minecraft:villager,name="""&B22&""",limit=1] add npc_"&LOWER(B22) -> /tag @e[type=minecraft:villager,name="Aristotle",limit=1] add npc_aristotle
A23: Trinsic | B23: Jean | C23: =IF(ISNA(VLOOKUP(A23&"|"&B23&"|"&"LOOK",'NPC Dialogue'!$A:$F,6,FALSE)),VLOOKUP(A23&"|"&B23&"|"&"You see..",'NPC Dialogue'!$A:$F,6,FALSE),VLOOKUP(A23&"|"&B23&"|"&"LOOK",'NPC Dialogue'!$A:$F,6,FALSE)) -> I am the Proprietor of Duelling Weapons, here. | D23: Weaponsmith | E23: ="/data merge entity @e[type=minecraft:villager,limit=1,sort=nearest] {CustomName:"""&B23&"""}" -> /data merge entity @e[type=minecraft:villager,limit=1,sort=nearest] {CustomName:"Jean"} | F23: ="/tag @e[type=minecraft:villager,name="""&B23&""",limit=1] add npc_"&LOWER(B23) -> /tag @e[type=minecraft:villager,name="Jean",limit=1] add npc_jean
A24: Trinsic | B24: Jumar | C24: =IF(ISNA(VLOOKUP(A24&"|"&B24&"|"&"LOOK",'NPC Dialogue'!$A:$F,6,FALSE)),VLOOKUP(A24&"|"&B24&"|"&"You see..",'NPC Dialogue'!$A:$F,6,FALSE),VLOOKUP(A24&"|"&B24&"|"&"LOOK",'NPC Dialogue'!$A:$F,6,FALSE)) -> I am the Proprietor of Duelling Armour, here. | D24: Armorer | E24: ="/data merge entity @e[type=minecraft:villager,limit=1,sort=nearest] {CustomName:"""&B24&"""}" -> /data merge entity @e[type=minecraft:villager,limit=1,sort=nearest] {CustomName:"Jumar"} | F24: ="/tag @e[type=minecraft:villager,name="""&B24&""",limit=1] add npc_"&LOWER(B24) -> /tag @e[type=minecraft:villager,name="Jumar",limit=1] add npc_jumar
A25: Trinsic | B25: Kline | C25: =IF(ISNA(VLOOKUP(A25&"|"&B25&"|"&"LOOK",'NPC Dialogue'!$A:$F,6,FALSE)),VLOOKUP(A25&"|"&B25&"|"&"You see..",'NPC Dialogue'!$A:$F,6,FALSE),VLOOKUP(A25&"|"&B25&"|"&"LOOK",'NPC Dialogue'!$A:$F,6,FALSE)) -> A searching paladin! | D25: Librarian | E25: ="/data merge entity @e[type=minecraft:villager,limit=1,sort=nearest] {CustomName:"""&B25&"""}" -> /data merge entity @e[type=minecraft:villager,limit=1,sort=nearest] {CustomName:"Kline"} | F25: ="/tag @e[type=minecraft:villager,name="""&B25&""",limit=1] add npc_"&LOWER(B25) -> /tag @e[type=minecraft:villager,name="Kline",limit=1] add npc_kline
A26: Trinsic | B26: Lexington | C26: =IF(ISNA(VLOOKUP(A26&"|"&B26&"|"&"LOOK",'NPC Dialogue'!$A:$F,6,FALSE)),VLOOKUP(A26&"|"&B26&"|"&"You see..",'NPC Dialogue'!$A:$F,6,FALSE),VLOOKUP(A26&"|"&B26&"|"&"LOOK",'NPC Dialogue'!$A:$F,6,FALSE)) -> A shining paladin. | D26: Armorer | E26: ="/data merge entity @e[type=minecraft:villager,limit=1,sort=nearest] {CustomName:"""&B26&"""}" -> /data merge entity @e[type=minecraft:villager,limit=1,sort=nearest] {CustomName:"Lexington"} | F26: ="/tag @e[type=minecraft:villager,name="""&B26&""",limit=1] add npc_"&LOWER(B26) -> /tag @e[type=minecraft:villager,name="Lexington",limit=1] add npc_lexington
A27: Trinsic | B27: Rigmore | C27: =IF(ISNA(VLOOKUP(A27&"|"&B27&"|"&"LOOK",'NPC Dialogue'!$A:$F,6,FALSE)),VLOOKUP(A27&"|"&B27&"|"&"You see..",'NPC Dialogue'!$A:$F,6,FALSE),VLOOKUP(A27&"|"&B27&"|"&"LOOK",'NPC Dialogue'!$A:$F,6,FALSE)) -> A strong paladin. | D27: Armorer | E27: ="/data merge entity @e[type=minecraft:villager,limit=1,sort=nearest] {CustomName:"""&B27&"""}" -> /data merge entity @e[type=minecraft:villager,limit=1,sort=nearest] {CustomName:"Rigmore"} | F27: ="/tag @e[type=minecraft:villager,name="""&B27&""",limit=1] add npc_"&LOWER(B27) -> /tag @e[type=minecraft:villager,name="Rigmore",limit=1] add npc_rigmore
A28: Trinsic | B28: Swindrik | C28: =IF(ISNA(VLOOKUP(A28&"|"&B28&"|"&"LOOK",'NPC Dialogue'!$A:$F,6,FALSE)),VLOOKUP(A28&"|"&B28&"|"&"You see..",'NPC Dialogue'!$A:$F,6,FALSE),VLOOKUP(A28&"|"&B28&"|"&"LOOK",'NPC Dialogue'!$A:$F,6,FALSE)) -> A tall wizard. | D28: Cleric | E28: ="/data merge entity @e[type=minecraft:villager,limit=1,sort=nearest] {CustomName:"""&B28&"""}" -> /data merge entity @e[type=minecraft:villager,limit=1,sort=nearest] {CustomName:"Swindrik"} | F28: ="/tag @e[type=minecraft:villager,name="""&B28&""",limit=1] add npc_"&LOWER(B28) -> /tag @e[type=minecraft:villager,name="Swindrik",limit=1] add npc_swindrik
A29: Trinsic | B29: Terran | C29: =IF(ISNA(VLOOKUP(A29&"|"&B29&"|"&"LOOK",'NPC Dialogue'!$A:$F,6,FALSE)),VLOOKUP(A29&"|"&B29&"|"&"You see..",'NPC Dialogue'!$A:$F,6,FALSE),VLOOKUP(A29&"|"&B29&"|"&"LOOK",'NPC Dialogue'!$A:$F,6,FALSE)) -> I am the Proprietor of The Keg Tap, here. | D29: Butcher | E29: ="/data merge entity @e[type=minecraft:villager,limit=1,sort=nearest] {CustomName:"""&B29&"""}" -> /data merge entity @e[type=minecraft:villager,limit=1,sort=nearest] {CustomName:"Terran"} | F29: ="/tag @e[type=minecraft:villager,name="""&B29&""",limit=1] add npc_"&LOWER(B29) -> /tag @e[type=minecraft:villager,name="Terran",limit=1] add npc_terran
A30: Trinsic | B30: Terrin | C30: =IF(ISNA(VLOOKUP(A30&"|"&B30&"|"&"LOOK",'NPC Dialogue'!$A:$F,6,FALSE)),VLOOKUP(A30&"|"&B30&"|"&"You see..",'NPC Dialogue'!$A:$F,6,FALSE),VLOOKUP(A30&"|"&B30&"|"&"LOOK",'NPC Dialogue'!$A:$F,6,FALSE)) -> A scared, cowering nitwit | D30: Nitwit | E30: ="/data merge entity @e[type=minecraft:villager,limit=1,sort=nearest] {CustomName:"""&B30&"""}" -> /data merge entity @e[type=minecraft:villager,limit=1,sort=nearest] {CustomName:"Terrin"} | F30: ="/tag @e[type=minecraft:villager,name="""&B30&""",limit=1] add npc_"&LOWER(B30) -> /tag @e[type=minecraft:villager,name="Terrin",limit=1] add npc_terrin
A31: Trinsic | B31: Winthrop | C31: =IF(ISNA(VLOOKUP(A31&"|"&B31&"|"&"LOOK",'NPC Dialogue'!$A:$F,6,FALSE)),VLOOKUP(A31&"|"&B31&"|"&"You see..",'NPC Dialogue'!$A:$F,6,FALSE),VLOOKUP(A31&"|"&B31&"|"&"LOOK",'NPC Dialogue'!$A:$F,6,FALSE)) -> A scruffy merchant. | D31: Fisherman | E31: ="/data merge entity @e[type=minecraft:villager,limit=1,sort=nearest] {CustomName:"""&B31&"""}" -> /data merge entity @e[type=minecraft:villager,limit=1,sort=nearest] {CustomName:"Winthrop"} | F31: ="/tag @e[type=minecraft:villager,name="""&B31&""",limit=1] add npc_"&LOWER(B31) -> /tag @e[type=minecraft:villager,name="Winthrop",limit=1] add npc_winthrop
A32: Trinsic | B32: Zajac | C32: =IF(ISNA(VLOOKUP(A32&"|"&B32&"|"&"LOOK",'NPC Dialogue'!$A:$F,6,FALSE)),VLOOKUP(A32&"|"&B32&"|"&"You see..",'NPC Dialogue'!$A:$F,6,FALSE),VLOOKUP(A32&"|"&B32&"|"&"LOOK",'NPC Dialogue'!$A:$F,6,FALSE)) -> I am the Proprietor of the Honorable Inn, here. | D32: Shepherd | E32: ="/data merge entity @e[type=minecraft:villager,limit=1,sort=nearest] {CustomName:"""&B32&"""}" -> /data merge entity @e[type=minecraft:villager,limit=1,sort=nearest] {CustomName:"Zajac"} | F32: ="/tag @e[type=minecraft:villager,name="""&B32&""",limit=1] add npc_"&LOWER(B32) -> /tag @e[type=minecraft:villager,name="Zajac",limit=1] add npc_zajac
A33: Yew | B33: Beggar | C33: =IF(ISNA(VLOOKUP(A33&"|"&B33&"|"&"LOOK",'NPC Dialogue'!$A:$F,6,FALSE)),VLOOKUP(A33&"|"&B33&"|"&"You see..",'NPC Dialogue'!$A:$F,6,FALSE),VLOOKUP(A33&"|"&B33&"|"&"LOOK",'NPC Dialogue'!$A:$F,6,FALSE)) -> A poor beggar. | D33: Nitwit | E33: ="/data merge entity @e[type=minecraft:villager,limit=1,sort=nearest] {CustomName:"""&B33&"""}" -> /data merge entity @e[type=minecraft:villager,limit=1,sort=nearest] {CustomName:"Beggar"} | F33: ="/tag @e[type=minecraft:villager,name="""&B33&""",limit=1] add npc_"&SUBSTITUTE(LOWER(B33)," ","_") -> /tag @e[type=minecraft:villager,name="Beggar",limit=1] add npc_beggar | G33: =B33 -> Beggar | H33: =MID(F33,I33+4,99) -> npc_beggar | I33: =FIND("add npc",F33) -> 56
A34: Yew | B34: Calumny | C34: =IF(ISNA(VLOOKUP(A34&"|"&B34&"|"&"LOOK",'NPC Dialogue'!$A:$F,6,FALSE)),VLOOKUP(A34&"|"&B34&"|"&"You see..",'NPC Dialogue'!$A:$F,6,FALSE),VLOOKUP(A34&"|"&B34&"|"&"LOOK",'NPC Dialogue'!$A:$F,6,FALSE)) -> A solemn druid. | D34: Librarian - inside eastern tree | E34: ="/data merge entity @e[type=minecraft:villager,limit=1,sort=nearest] {CustomName:"""&B34&"""}" -> /data merge entity @e[type=minecraft:villager,limit=1,sort=nearest] {CustomName:"Calumny"} | F34: ="/tag @e[type=minecraft:villager,name="""&B34&""",limit=1] add npc_"&SUBSTITUTE(LOWER(B34)," ","_") -> /tag @e[type=minecraft:villager,name="Calumny",limit=1] add npc_calumny | G34: =B34 -> Calumny | H34: =MID(F34,I34+4,99) -> npc_calumny | I34: =FIND("add npc",F34) -> 57
A35: Yew | B35: Court Guard | C35: =IF(ISNA(VLOOKUP(A35&"|"&B35&"|"&"LOOK",'NPC Dialogue'!$A:$F,6,FALSE)),VLOOKUP(A35&"|"&B35&"|"&"You see..",'NPC Dialogue'!$A:$F,6,FALSE),VLOOKUP(A35&"|"&B35&"|"&"LOOK",'NPC Dialogue'!$A:$F,6,FALSE)) -> A tall guard | D35: Leathermaker | E35: ="/data merge entity @e[type=minecraft:villager,limit=1,sort=nearest] {CustomName:"""&B35&"""}" -> /data merge entity @e[type=minecraft:villager,limit=1,sort=nearest] {CustomName:"Court Guard"} | F35: ="/tag @e[type=minecraft:villager,name="""&B35&""",limit=1] add npc_"&SUBSTITUTE(LOWER(B35)," ","_") -> /tag @e[type=minecraft:villager,name="Court Guard",limit=1] add npc_court_guard | G35: =B35 -> Court Guard | H35: =MID(F35,I35+4,99) -> npc_court_guard | I35: =FIND("add npc",F35) -> 61
A36: Yew | B36: A.Druid | C36: =IF(ISNA(VLOOKUP(A36&"|"&B36&"|"&"LOOK",'NPC Dialogue'!$A:$F,6,FALSE)),VLOOKUP(A36&"|"&B36&"|"&"You see..",'NPC Dialogue'!$A:$F,6,FALSE),VLOOKUP(A36&"|"&B36&"|"&"LOOK",'NPC Dialogue'!$A:$F,6,FALSE)) -> #N/A | D36: Librarian - wandering around the grounds | E36: ="/data merge entity @e[type=minecraft:villager,limit=1,sort=nearest] {CustomName:"""&B36&"""}" -> /data merge entity @e[type=minecraft:villager,limit=1,sort=nearest] {CustomName:"A.Druid"} | F36: ="/tag @e[type=minecraft:villager,name="""&B36&""",limit=1] add npc_"&SUBSTITUTE(LOWER(B36)," ","_") -> /tag @e[type=minecraft:villager,name="A.Druid",limit=1] add npc_a.druid | G36: =B36 -> A.Druid | H36: =MID(F36,I36+4,99) -> npc_a.druid | I36: =FIND("add npc",F36) -> 57
A37: Yew | B37: DWP | C37: =IF(ISNA(VLOOKUP(A37&"|"&B37&"|"&"LOOK",'NPC Dialogue'!$A:$F,6,FALSE)),VLOOKUP(A37&"|"&B37&"|"&"You see..",'NPC Dialogue'!$A:$F,6,FALSE),VLOOKUP(A37&"|"&B37&"|"&"LOOK",'NPC Dialogue'!$A:$F,6,FALSE)) -> A wise druid. | D37: Librarian - Welcomer | E37: ="/data merge entity @e[type=minecraft:villager,limit=1,sort=nearest] {CustomName:"""&B37&"""}" -> /data merge entity @e[type=minecraft:villager,limit=1,sort=nearest] {CustomName:"DWP"} | F37: ="/tag @e[type=minecraft:villager,name="""&B37&""",limit=1] add npc_"&SUBSTITUTE(LOWER(B37)," ","_") -> /tag @e[type=minecraft:villager,name="DWP",limit=1] add npc_dwp | G37: =B37 -> DWP | H37: =MID(F37,I37+4,99) -> npc_dwp | I37: =FIND("add npc",F37) -> 53
A38: Yew | B38: Frida | C38: =IF(ISNA(VLOOKUP(A38&"|"&B38&"|"&"LOOK",'NPC Dialogue'!$A:$F,6,FALSE)),VLOOKUP(A38&"|"&B38&"|"&"You see..",'NPC Dialogue'!$A:$F,6,FALSE),VLOOKUP(A38&"|"&B38&"|"&"LOOK",'NPC Dialogue'!$A:$F,6,FALSE)) -> A withered form. | D38: Nitwit - in Healer | E38: ="/data merge entity @e[type=minecraft:villager,limit=1,sort=nearest] {CustomName:"""&B38&"""}" -> /data merge entity @e[type=minecraft:villager,limit=1,sort=nearest] {CustomName:"Frida"} | F38: ="/tag @e[type=minecraft:villager,name="""&B38&""",limit=1] add npc_"&SUBSTITUTE(LOWER(B38)," ","_") -> /tag @e[type=minecraft:villager,name="Frida",limit=1] add npc_frida | G38: =B38 -> Frida | H38: =MID(F38,I38+4,99) -> npc_frida | I38: =FIND("add npc",F38) -> 55
A39: Yew | B39: Guard | C39: =IF(ISNA(VLOOKUP(A39&"|"&B39&"|"&"LOOK",'NPC Dialogue'!$A:$F,6,FALSE)),VLOOKUP(A39&"|"&B39&"|"&"You see..",'NPC Dialogue'!$A:$F,6,FALSE),VLOOKUP(A39&"|"&B39&"|"&"LOOK",'NPC Dialogue'!$A:$F,6,FALSE)) -> A big guard | D39: Leathermaker - near Welcomer | E39: ="/data merge entity @e[type=minecraft:villager,limit=1,sort=nearest] {CustomName:"""&B39&"""}" -> /data merge entity @e[type=minecraft:villager,limit=1,sort=nearest] {CustomName:"Guard"} | F39: ="/tag @e[type=minecraft:villager,name="""&B39&""",limit=1] add npc_"&SUBSTITUTE(LOWER(B39)," ","_") -> /tag @e[type=minecraft:villager,name="Guard",limit=1] add npc_guard | G39: =B39 -> Guard | H39: =MID(F39,I39+4,99) -> npc_guard | I39: =FIND("add npc",F39) -> 55
A40: Yew | B40: Jaana | C40: =IF(ISNA(VLOOKUP(A40&"|"&B40&"|"&"LOOK",'NPC Dialogue'!$A:$F,6,FALSE)),VLOOKUP(A40&"|"&B40&"|"&"You see..",'NPC Dialogue'!$A:$F,6,FALSE),VLOOKUP(A40&"|"&B40&"|"&"LOOK",'NPC Dialogue'!$A:$F,6,FALSE)) -> A quiet druid | D40: Shepherd - north side of Fire | E40: ="/data merge entity @e[type=minecraft:villager,limit=1,sort=nearest] {CustomName:"""&B40&"""}" -> /data merge entity @e[type=minecraft:villager,limit=1,sort=nearest] {CustomName:"Jaana"} | F40: ="/tag @e[type=minecraft:villager,name="""&B40&""",limit=1] add npc_"&SUBSTITUTE(LOWER(B40)," ","_") -> /tag @e[type=minecraft:villager,name="Jaana",limit=1] add npc_jaana | G40: =B40 -> Jaana | H40: =MID(F40,I40+4,99) -> npc_jaana | I40: =FIND("add npc",F40) -> 55
...

Sheet gameDesignMisc
C3: Trinsic | D3: Lexington | E3: QUES | F3: The solving of quests brings ye honor! | G3: add this to game for HONOR scoreboard (for various mini-quests, in-game)
C4: Trinsic | D4: Skitle | E4: STON | F4: I have seen the purple stone used in the altars of truth and courage! | G4: this is U4's mechanic for needing to know how the colors matter.
C5: Trinsic | D5: Terrin | E5: What am I up to? | F5: I had been looking for the rune when a skeleton appeared! | G5: For random, non-magenta shulkers, there's a 20% chance a skeleton will pop out! For the black one, there's a wither skeleton egg and wither may also pop out…?
C8: Jhelom | G8: Has 1-2 of the three metallurgists
C10: Lycaeum | G10: In the library there is one bookshelf which looks different -- 4.N.(4,8).2.1 -- it's missing a book. If you look to the right on floor thru grating you'll find a grey shulker box containing the missing book
C11: Minoc | F11: No Trades set up yet in Minoc -- remember to add Fire Protection Potion to one of them! (to retrieve rune from forge)
B13: We'll have to put these Vesperian clues into other towns:
C14: Villages | D14: Vesper | E14: Gem | F14: MANT | G14: Since humility is the opposite of pride, so is its mantra!
C15: Villages | D15: Vesper | E15: Plain | F15: HUMI | G15: When the 3 principles of virtue combine in eight ways pride has no virtue!

Sheet UsefulTagCmds
A1: Tagging Villagers as NPCs
A2: -------------------------
A3: /data merge entity @e[type=minecraft:villager,limit=1,sort=nearest] {CustomName:"Sasha"}
A4: /tag @e[type=minecraft:villager,name="Tyrone",limit=1] add npc_sasha
A7: REMOVING TAGS APPLIED INCORRECTLY:
A8: /tag @e[type=minecraft:villager,name="Mariah",limit=1] remove npc_shazom
A10: -----------------
A11: Make a villager a NITWIT:
A13: /data merge entity @e[type=minecraft:villager,limit=1,sort=nearest] {VillagerData:{profession:"minecraft:nitwit"}}

Sheet Runes_Stones_Mantras
A1: category | B1: virtue_or_color | C1: location(s) | D1: how_to_obtain_chain | E1: answer
A2: Rune | B2: Honesty | C2: Moonglow | D2: Christen ("My friend William knows where the rune of honesty is.") -> William ("Search for the rune of honesty by Mariah's gold!") | E2: Search by Mariah's gold, in Moonglow
A3: Rune | B3: Compassion | C3: Britain | D3: Sprite, if given help/food ("In return I shall tell thee that Pepper knows of the rune!") -> Pepper ("The rune of compassion lies at the end of a hall somewhere in this towne.") | E3: End of a hall somewhere in Britain
A4: Rune | B4: Valor | C4: Jhelom | D4: Lord Robert, if answered YES ("Thou dost deserve the rune, ask Nostro!") -> Nostro ("The rune is buried in a tower!") | E4: Buried in a tower in Jhelom
A5: Rune | B5: Sacrifice | C5: Minoc | D5: Gimble, if given a coin ("Remember Azure knows of the rune!") -> Azure ("I carve runes for passage into the shrines!", SACR: "Ask my sister, Mischief.") -> Mischief ("The rune of sacrifice is hard to get. It lies within the fires of the forge!") | E5: Azure the tinker carves it; Mischief says it lies within the fires of the forge (Minoc)
A6: Rune | B6: Justice | C6: Yew | D6: Druid, answered NO to "Dost thou have the rune?" ("Ask Talfourd for he knows of the rune.") -> Talfourd ("It is hidden well!") | E6: Hidden well (no exact spot given) - ask Talfourd, the judge, in Yew
A7: Rune | B7: Honor | C7: Trinsic | D7: Kline ("A man named Winthrop knows of the rune!") -> Winthrop ("There is a small child who knew named... Terrin.") -> Terrin ("It is buried in the southwest corner of towne.") | E7: Buried in the southwest corner of Trinsic
A8: Rune | B8: Spirituality | C8: Skara Brae / Castle Britannia | D8: Granted, if given food/money ("the ankh knows of the rune... my friend Ambule knows the mantra!") -> the Ankh of Spirituality (needs the mantra 'OM' spoken to it first -> "Search for the rune of spirituality in the treasure chamber of Britannia!") | E8: Treasure chamber of Castle Britannia (must know mantra OM first - see Mantras)
A9: Rune | B9: Humility | C9: Magincia / Paws | D9: Splot / Ruskin ("ask the snake of the rune...") -> Nate the Snake ("The sacred rune of humility was banished from this city. Ask Barren in Paws!") -> Barren, in Paws ("Search the hills in the south-east corner of town!") [Wheatpin also hints: "Around there in the nook of the mountains!"] | E9: South-east corner of Paws, in the hills/mountains
A10: Mantra | B10: Honesty | C10: Moonglow | D10: Cromwell states it directly: "The mantra of the shrine of honesty is 'AHM'." | E10: AHM
A11: Mantra | B11: Compassion | C11: Britain | D11: Child (quiz - answer NO: "Ask Cricket!") -> Cricket states it directly: "The mantra for the shrine of compassion is 'MU'!" | E11: MU
A12: Mantra | B12: Valor | C12: Jhelom | D12: Sir Hrothgar ("The mantra need be known, ask Aesop!") -> Aesop ("The mantra of valor is 'RA' use it in the shrine on the next isle!") | E12: RA
... A25: Stone | B25: Black | C25: Cove / a Moongate | D25: Nate the Snake ("Those who seek the black stone need ask at the pub in Britain!") -> Bartender in Pubs, for 20 gold ("the only one who knows where it lies is the wizard Merlin.") -> Merlin, in Cove ("The black stone is caught in a moon gate!... Stand where the gate of both moons dark shall appear. Search when the moons go dark!") | E25: Caught in a moongate when both moons are dark
A26: PreciousItem-MC

Sheet QuestionTriggers
A1: key | B1: town_type | C1: town_name | D1: npc_name | E1: trigger_word | F1: question
A2: =B2&"|"&C2&"|"&D2&"|"&E2 -> Castles|Castle Britannia|Chuckles|JEST | B2: Castles | C2: Castle Britannia | D2: Chuckles | E2: JEST | F2: Hast thou an ankh?
A3: =B3&"|"&C3&"|"&D3&"|"&E3 -> Castles|Castle Britannia|Gate Guard|CAST | B3: Castles | C3: Castle Britannia | D3: Gate Guard | E3: CAST | F3: Do you seek Lord British?
A4: =B4&"|"&C4&"|"&D4&"|"&E4 -> Castles|Castle Britannia|Treasury Guard|TREA | B4: Castles | C4: Castle Britannia | D4: Treasury Guard | E4: TREA | F4: Do you mean to steal?
A5: =B5&"|"&C5&"|"&D5&"|"&E5 -> Castles|Castle Britannia|Guard (2nd Floor)|GUAR | B5: Castles | C5: Castle Britannia | D5: Guard (2nd Floor) | E5: GUAR | F5: Art thou the most valiant warrior?
A6: =B6&"|"&C6&"|"&D6&"|"&E6 -> Castles|Castle Britannia|Jester Twins|BARD | B6: Castles | C6: Castle Britannia | D6: Jester Twins | E6: BARD | F6: Dost thou like the music?
A7: =B7&"|"&C7&"|"&D7&"|"&E7 -> Castles|Castle Britannia|Joshua|RIDD | B7: Castles | C7: Castle Britannia | D7: Joshua | E7: RIDD | F7: More?
A8: =B8&"|"&C8&"|"&D8&"|"&E8 -> Castles|Castle Britannia|Juliet|ONE | B8: Castles | C8: Castle Britannia | D8: Juliet | E8: ONE | F8: Know ye this?
A9: =B9&"|"&C9&"|"&D9&"|"&E9 -> Castles|Castle Britannia|Landri|PERI | B9: Castles | C9: Castle Britannia | D9: Landri | E9: PERI | F9: Wilt thou go on?
A10: =B10&"|"&C10&"|"&D10&"|"&E10 -> Castles|Castle Britannia|Le Chef|COOK | B10: Castles | C10: Castle Britannia | D10: Le Chef | E10: COOK | F10: Do you eat?
A11: =B11&"|"&C11&"|"&D11&"|"&E11 -> Castles|Castle Britannia|Prisoner|PRIS | B11: Castles | C11: Castle Britannia | D11: Prisoner | E11: PRIS | F11: Are you a pirate?
A12: =B12&"|"&C12&"|"&D12&"|"&E12 -> Castles|Castle Britannia|Reaper|THIN | B12: Castles | C12: Castle Britannia | D12: Reaper | E12: THIN | F12: Will you seek this thing?
A13: =B13&"|"&C13&"|"&D13&"|"&E13 -> Castles|Castle Britannia|Seesha|COUN | B13: Castles | C13: Castle Britannia | D13: Seesha | E13: COUN | F13: Fight ye for Britannia?
... A242: =B242&"|"&C242&"|"&D242&"|"&E242 -> Villages|Cove|Charm|AXIO | B242: Villages | C242: Cove | D242: Charm | E242: AXIO | F242: Know ye what they are?

Sheet MC-InterTownDependencies
A1: Town | B1: Needs | C1: Notes | D1: Town | E1: Has | F1: Notes
A2: Yew | B2: Oak Leaves (for druids/potions) | C2: L1 trade to bring in a lot of Oak Leaves unlocks JusticePotion | D2: <skara?> | E2: Hoe with Silk Touch

Sheet TheGypsy
A1: town_type | B1: town_name | C1: npc_name | D1: keyword | E1: reply
A2: Earth | B2: The Gypsy | C2: The Gypsy | D2: (intro) | E2: The Gypsy gives ethical challenges, to which the Stranger responds by choosing between two Virtues.
A3: Earth | B3: The Gypsy | C3: The Gypsy | D3: Honesty vs. Compassion | E3: Entrusted to deliver an uncounted purse of gold, thou dost meet a poor beggar. Dost thou A) deliver the gold knowing the Trust in thee was well-placed; or B) show Compassion, giving the Beggar a coin, knowing it won’t be missed?
A4: Earth | B4: The Gypsy | C4: The Gypsy | D4: Honesty vs. Valor | E4: Thou hast been prohibited by thy absent Lord from joining thy friends in a close pitched battle. Dost thou A) refrain, so thou may Honestly claim obedience; or B) show Valor, and aid thy comrades, knowing thou may deny it later?
A5: Earth | B5: The Gypsy | C5: The Gypsy | D5: Honesty vs. Justice | E5: A merchant owes thy friend money, now long past due. Thou dost see the same merchant drop a purse of gold. Dost thou A) Honestly return the purse intact; or B) Justly give thy friend a portion of the gold first?
A6: Earth | B6: The Gypsy | C6: The Gypsy | D6: Honesty vs. Sacrifice | E6: Thee and thy friend are valiant but penniless warriors. Thou both go out to slay a mighty dragon. Thy friend thinks he slew it, thee did. When asked, dost thou A) Truthfully claim the gold; or B) Allow thy friend the large reward?
A7: Earth | B7: The Gypsy | C7: The Gypsy | D7: Honesty vs. Honor | E7: Thou art sworn to protect thy Lord at any cost, yet thou knowest he hath committed a crime. Authorities ask thee of the affair, dost thou A) break thine oath by Honestly speaking; or B) uphold Honor by silently keeping thine oath?
A8: Earth | B8: The Gypsy | C8: The Gypsy | D8: Honesty vs. Spirituality | E8: Thy friend seeks admittance to thy Spiritual order. Thou art asked to vouch for his purity of Spirit, of which thou art unsure. Dost thou A) Honestly express thy doubt; or B) Vouch for him, hoping for his Spiritual improvement?
A9: Earth | B9: The Gypsy | C9: The Gypsy | D9: Honesty vs. Humility | E9: Thy Lord mistakenly believes he slew a dragon. Thou hast proof that thy lance felled the beast. When asked, dost thou A) Honestly claim the kill and the prize; or B) Humbly permit thy Lord his belief?
A10: Earth | B10: The Gypsy | C10: The Gypsy | D10: Compassion vs. Valor | E10: Thou dost manage to disarm thy mortal enemy in a duel. He is at thy mercy. Dost thou A) show Compassion by permitting him to yield; or B) slay him as expected of a Valiant duelist?
A11: Earth | B11: The Gypsy | C11: The Gypsy | D11: Compassion vs. Justice | E11: After 20 years thou hast found the slayer of thy best friends. The villain proves to be a man who provides the sole support for a young girl. Dost thou A) spare him in Compassion for the girl; or B) slay him in the name of Justice?
A12: Earth | B12: The Gypsy | C12: The Gypsy | D12: Compassion vs. Sacrifice | E12: Thee and thy friends have been routed and ordered to retreat. In defiance of thy orders, dost thou A) stop in Compassion to aid a wounded companion; or B) Sacrifice thyself to slow the pursuing enemy, so others can escape?
... A30: Earth | B30: The Gypsy | C30: The Gypsy | D30: Spirituality vs. Humility | E30: Thy parents wish thee to become an apprentice. Two positions are available. Dost thou A) Become an acolyte in the Spiritual order; or B) Become an assistant to a humble village cobbler?

Sheet Barkeeps
A1: town_type | B1: town_name | C1: npc_name | D1: keyword | E1: reply
A2: Towns | B2: ALL | C2: Bartender | D2: (intro) | E2: The bartender will give helpful advice if the Stranger overpays for ale.
A3: Towns | B3: Britain | C3: Bartender | D3: Black stone (20 gold) | E3: Ah, the Black Stone. Yes I’ve heard of it. But, the only one who knows where it lies is the wizard Merlin.
A4: Towns | B4: Jhelom | C4: Bartender | D4: Sextant (30 gold) | E4: For navigation a Sextant is vital... Ask for item "D" in the Guild shops!
A5: Towns | B5: Trinsic | C5: Bartender | D5: White stone (10 gold) | E5: Now let me see... Yes it was the old Hermit... Sloven! He is tough to find, lives near Lock Lake I hear.
A6: Villages | B6: Paws | C6: Bartender | D6: Mandrake (40 gold) | E6: The last person I knew that had any Mandrake was an old alchemist named Calumny.
A7: Villages | B7: Bucaneer's Den | C7: Bartender | D7: Skull (99 gold) | E7: If thou must know of that evilest of all things... find the beggar Jude. He is very very poor!
A8: Villages | B8: Vesper | C8: Bartender | D8: Nightshade (25 gold) | E8: Of Nightshade I know but this... Seek out Virgil or thou shalt miss! Try in Trinsic!
